Workbook

Sheet Resumo Geral
A1: 📊 DASHBOARD FINANCEIRO COMPLETO - FAMÍLIA PALOMO | P1: Mês | Q1: Entradas | R1: Saídas | S1: Paciente | T1: Reembolso
A2: Período: Janeiro a Maio/2026 | Conta: Ag 3767 | CC 29709-0 | Itaú Personnalité | Atualizado: 19/06/2026 | P2: Jan | Q2: =C6 -> 95097.81 | R2: =D6 -> 87588.14 | S2: Priscila | T2: =N13 -> #REF!
P3: Fev | Q3: =C7 -> 20972.27 | R3: =D7 -> 32688.76 | S3: João | T3: =N14 -> #REF!
A4: 💰 RESUMO FINANCEIRO MENSAL | K4: 🏥 REEMBOLSOS MÉDICOS - CIGNA/McKINSEY | P4: Mar | Q4: =C8 -> 106005.86 | R4: =D8 -> 86875.34 | S4: Ana Luisa | T4: =N15 -> #REF!
A5: Mês | B5: Saldo Inicial | C5: Entradas | D5: Saídas | E5: Saldo Mov. | F5: Saldo Final | G5: Investimentos | H5: Var. % | K5: 📈 Resumo Geral | P5: Mês | Q5: Entradas | R5: Saídas | S5: Luisa | T5: =N16 -> #REF!
A6: Janeiro/26 | B6: ='janeiro 26'!B5 -> 5021.19 | C6: ='Consolidado Jan-Mai'!B42 -> 95097.81 | D6: ='Consolidado Jan-Mai'!B31 -> 87588.14 | E6: =C6-D6 -> 7509.67 | F6: ='janeiro 26'!B8 -> 13241.28 | G6: =0 -> 0 | K6: Total Claims | L6: =#REF! -> #REF! | N6: Valor Médio/Claim | O6: =#REF! -> #REF! | P6: Jan | Q6: =C6 -> 95097.81 | R6: =D6 -> 87588.14
A7: Fevereiro/26 | B7: ='fevereiro 26'!B5 -> 13241.28 | C7: ='Consolidado Jan-Mai'!C42 -> 20972.27 | D7: ='Consolidado Jan-Mai'!C31 -> 32688.76 | E7: =C7-D7 -> -11716.49 | F7: ='fevereiro 26'!B8 -> 1525.05 | G7: =0 -> 0 | H7: =IFERROR((D7-D6)/D6,0) -> -0.62679011 | K7: Valor Solicitado | L7: =#REF! -> #REF! | N7: Maior Reembolso | O7: =#REF! -> #REF! | P7: Fev | Q7: =C7 -> 20972.27 | R7: =D7 -> 32688.76
A8: Março/26 | B8: ='março 26'!B5 -> 1525.05 | C8: ='Consolidado Jan-Mai'!D42 -> 106005.86 | D8: ='Consolidado Jan-Mai'!D31 -> 86875.34 | E8: =C8-D8 -> 19130.52 | F8: ='março 26'!B8 -> 20656.2 | G8: ='março 26'!H8 -> 42620 | H8: =IFERROR((D8-D7)/D7,0) -> 1.6576517 | K8: Total Reembolsado | L8: =#REF! -> #REF! | N8: Taxa Cobertura | O8: =#REF! -> #REF! | P8: Mar | Q8: =C8 -> 106005.86 | R8: =D8 -> 86875.34
A9: Abril/26 | B9: ='abril 26'!B5 -> 20656.2 | C9: ='Consolidado Jan-Mai'!E42 -> 37961.45 | D9: ='Consolidado Jan-Mai'!E31 -> 32607.71 | E9: =C9-D9 -> 5353.74 | F9: ='abril 26'!B8 -> 26011.36 | G9: ='abril 26'!H13 -> 1000 | H9: =IFERROR((D9-D8)/D8,0) -> -0.62466092 | K9: Diferença (Glosas) | L9: =#REF! -> #REF! | P9: Abr | Q9: =C9 -> 37961.45 | R9: =D9 -> 32607.71
A10: Maio/26 | B10: ='maio 26'!B5 -> 26011.36 | C10: ='Consolidado Jan-Mai'!F42 -> 46299.59 | D10: ='Consolidado Jan-Mai'!F31 -> 50830.84 | E10: =C10-D10 -> -4531.25 | F10: ='maio 26'!B8 -> 21481.28 | G10: ='maio 26'!H6 -> 17000 | H10: =IFERROR((D10-D9)/D9,0) -> 0.55885955 | P10: Mai | Q10: =C10 -> 46299.59 | R10: =D10 -> 50830.84
A11: TOTAL | B11: =B6 -> 5021.19 | C11: =SUM(C6:C10) -> 306336.98 | D11: =SUM(D6:D10) -> 290590.79 | E11: =SUM(E6:E10) -> 15746.19 | F11: =F10 -> 21481.28 | G11: =SUM(G6:G10) -> 60620 | H11: =IFERROR((D10-D6)/D6,0) -> -0.4196607 | K11: 👥 Por Beneficiário | P11: Cartão | Q11: =C18 -> 42118.14
A12: MÉDIA MENSAL | C12: =AVERAGE(C6:C10) -> 61267.396 | D12: =AVERAGE(D6:D10) -> 58118.158 | E12: =AVERAGE(E6:E10) -> 3149.238 | G12: =AVERAGE(G6:G10) -> 12124 | K12: Paciente | L12: Claims | M12: Solicitado | N12: Reembolsado | O12: % Cobertura | P12: Escola | Q12: =C19 -> 36066.69
K13: Priscila | L13: =#REF! -> #REF! | M13: =#REF! -> #REF! | N13: =#REF! -> #REF! | O13: =N13/M13 -> #REF! | P13: Financiamento | Q13: =C20 -> 32019.47
A14: 📊 TOP 15 CATEGORIAS DE GASTOS (Jan-Mai) | F14: 🏠 ANÁLISE GASTOS FIXOS vs VARIÁVEIS | K14: João Guilherme | L14: =#REF! -> #REF! | M14: =#REF! -> #REF! | N14: =#REF! -> #REF! | O14: =N14/M14 -> #REF!
A15: # | B15: Categoria | C15: Total Gasto | D15: % Total | F15: Tipo | G15: Categoria | H15: Total 5 Meses | I15: Média/Mês | K15: Ana Luisa | L15: =#REF! -> #REF! | M15: =#REF! -> #REF! | N15: =#REF! -> #REF! | O15: =N15/M15 -> #REF! | P15: Mês | Q15: Saldo Mov.
A16: 1 | B16: Investimento | C16: ='Consolidado Jan-Mai'!G12 -> 60620 | D16: =C16/$D$11 -> 0.2086095 | G16: Financiamento | H16: ='Consolidado Jan-Mai'!G7 -> 32019.47 | I16: =H16/5 -> 6403.894 | K16: Luisa Juliana | L16: =#REF! -> #REF! | M16: =#REF! -> #REF! | N16: =#REF! -> #REF! | O16: =N16/M16 -> #REF! | P16: Jan | Q16: =E6 -> 7509.67
A17: 2 | B17: Transferência Interna | C17: ='Consolidado Jan-Mai'!G10 -> 51464 | D17: =C17/$D$11 -> 0.17710128 | G17: Escola | H17: ='Consolidado Jan-Mai'!G8 -> 36066.69 | I17: =H17/5 -> 7213.338 | K17: TOTAL | L17: =#REF! -> #REF! | M17: =#REF! -> #REF! | N17: =#REF! -> #REF! | O17: =N17/M17 -> #REF! | P17: Fev | Q17: =E7 -> -11716.49
A18: 3 | B18: Cartão | C18: ='Consolidado Jan-Mai'!G6 -> 42118.14 | D18: =C18/$D$11 -> 0.14493969 | G18: Condomínio | H18: ='Consolidado Jan-Mai'!G11 -> 7538.34 | I18: =H18/5 -> 1507.668 | P18: Mar | Q18: =E8 -> 19130.52
A19: 4 | B19: Escola | C19: ='Consolidado Jan-Mai'!G8 -> 36066.69 | D19: =C19/$D$11 -> 0.12411505 | G19: Seguro | H19: ='Consolidado Jan-Mai'!G22 -> 5231.83 | I19: =H19/5 -> 1046.366 | K19: 🏥 Por Tipo de Serviço | P19: Abr | Q19: =E9 -> 5353.74
A20: 5 | B20: Financiamento | C20: ='Consolidado Jan-Mai'!G7 -> 32019.47 | D20: =C20/$D$11 -> 0.11018749 | G20: Subtotal Fixos | H20: =SUM(H16:H19) -> 80856.33 | I20: =SUM(I16:I19) -> 16171.266 | K20: Tipo | L20: Claims | M20: Solicitado | N20: Reembolsado | P20: Mai | Q20: =E10 -> -4531.25
A21: 6 | B21: Transferência | C21: ='Consolidado Jan-Mai'!G9 -> 25840.77 | D21: =C21/$D$11 -> 0.088924945 | G21: Cartão | H21: ='Consolidado Jan-Mai'!G6 -> 42118.14 | I21: =H21/5 -> 8423.628 | K21: Consulta | L21: =#REF! -> #REF! | M21: =#REF! -> #REF! | N21: =#REF! -> #REF!
A22: 7 | B22: Condomínio | C22: ='Consolidado Jan-Mai'!G11 -> 7538.34 | D22: =C22/$D$11 -> 0.025941428 | G22: Compras | H22: ='Consolidado Jan-Mai'!G12 -> 60620 | I22: =H22/5 -> 12124 | K22: Terapia | L22: =#REF! -> #REF! | M22: =#REF! -> #REF! | N22: =#REF! -> #REF!
A23: 8 | B23: Terapia/Psicologia | C23: ='Consolidado Jan-Mai'!G13+'Consolidado Jan-Mai'!G14 -> 8170 | D23: =C23/$D$11 -> 0.028115137 | G23: Alimentação | H23: ='Consolidado Jan-Mai'!G13 -> 4170 | I23: =H23/5 -> 834 | K23: Honorário | L23: =#REF! -> #REF! | M23: =#REF! -> #REF! | N23: =#REF! -> #REF!
A24: 9 | B24: Compras | C24: ='Consolidado Jan-Mai'!G15 -> 6993.31 | D24: =C24/$D$11 -> 0.024065835 | G24: Terapia/Saúde | H24: ='Consolidado Jan-Mai'!G16+'Consolidado Jan-Mai'!G26 -> 2296 | I24: =H24/5 -> 459.2 | K24: Cirurgia | L24: =#REF! -> #REF! | M24: =#REF! -> #REF! | N24: =#REF! -> #REF!
A25: 10 | B25: IPTU | C25: ='Consolidado Jan-Mai'!G20 -> 2298.18 | D25: =C25/$D$11 -> 0.0079086471 | G25: Subtotal Variáveis | H25: =SUM(H21:H24) -> 109204.14 | I25: =SUM(I21:I24) -> 21840.828 | K25: Outros | L25: =#REF! -> #REF! | M25: =#REF! -> #REF! | N25: =#REF! -> #REF!
A26: 11 | B26: Alimentação | C26: ='Consolidado Jan-Mai'!G17 -> 1019.13 | D26: =C26/$D$11 -> 0.0035070967 | G26: TOTAL GASTOS REAIS | H26: =H20+H25 -> 190060.47 | I26: =I20+I25 -> 38012.094
A27: 12 | B27: Conta Luz | C27: ='Consolidado Jan-Mai'!G19 -> 1855.95 | D27: =C27/$D$11 -> 0.0063868163 | K27: 🏢 TOP 5 PRESTADORES MÉDICOS
A28: 13 | B28: Farmácia | C28: ='Consolidado Jan-Mai'!G16 -> 1717.87 | D28: =C28/$D$11 -> 0.0059116464 | F28: 🎓 DESPESAS ESCOLARES - 2026 | K28: Prestador | L28: Claims | M28: Solicitado | N28: Reembolsado
A29: 14 | B29: Internet/TV | C29: ='Consolidado Jan-Mai'!G18 -> 1616.49 | D29: =C29/$D$11 -> 0.0055627709 | F29: Total Anual Previsto | G29: ='Escola crianças'!D23 -> 43242.87 | K29: Dr. Luis Ricardo (cirurgia) | L29: =#REF! -> #REF! | M29: =#REF! -> #REF! | N29: =#REF! -> #REF!
A30: 15 | B30: Outros | C30: =D11-SUM(C16:C29) -> 11252.45 | D30: =C30/$D$11 -> 0.038722666 | F30: Média Mensal (12 meses) | G30: =F29/12 -> #VALUE! | K30: Karine Saito Psicologia | L30: =#REF! -> #REF! | M30: =#REF! -> #REF! | N30: =#REF! -> #REF! | P30: Mês | Q30: Saldo
B31: TOTAL SAÍDAS | C31: =D11 -> 290590.79 | D31: =SUM(D16:D30) -> 1 | F31: Pagamentos Realizados (Jan-Mai) | G31: ='Consolidado Jan-Mai'!G8 -> 36066.69 | K31: Wendy Paola (Terapia) | L31: =#REF! -> #REF! | M31: =#REF! -> #REF! | N31: =#REF! -> #REF! | P31: Jan | Q31: =E6 -> 7509.67
F32: Média Efetiva (5 meses) | G32: =F31/5 -> #VALUE! | K32: Rogério Ribeiro (Terapia) | L32: =#REF! -> #REF! | M32: =#REF! -> #REF! | N32: =#REF! -> #REF! | P32: Fev | Q32: =E7 -> -11716.49
A33: 📈 INDICADORES DE SAÚDE FINANCEIRA | F33: Diferença Prev. vs Real | G33: =F30-F32 -> #VALUE! | K33: Outros (diversos) | L33: =47-L29-L30-L31-L32 -> #REF! | M33: =M17-M29-M30-M31-M32 -> #REF! | N33: =N17-N29-N30-N31-N32 -> #REF! | P33: Mar | Q33: =E8 -> 19130.52
A34: Indicador | B34: Valor | C34: Meta/Referência | D34: Status | F34: Qtd Pagamentos | G34: 20 | P34: Abr | Q34: =E9 -> 5353.74
A35: Saldo Acumulado (5 meses) | B35: =E11 -> 15746.19 | C35: Meta: >R$10.000 | D35: =IF(B35>10000,"✅ Ótimo",IF(B35>0,"⚠️ Positivo","❌ Negativo")) -> ✅ Ótimo | F35: Próximo Vencimento | G35: 01/Jul (mensal) | P35: Mai | Q35: =E10 -> -4531.25
A36: Taxa de Poupança | B36: =IFERROR(E11/C11,0) -> 0.051401532 | C36: Meta: >10% | D36: =IF(B36>0.1,"✅ Ótimo",IF(B36>0.05,"⚠️ Adequado","❌ Baixa")) -> ⚠️ Adequado | K36: Paciente | L36: Reembolsado
A37: Média Entradas/Mês | B37: =C12 -> 61267.396 | C37: Referência | F37: 📊 EVOLUÇÃO MENSAL - PRINCIPAIS GASTOS | K37: Priscila | L37: =N13 -> #REF!
A38: Média Saídas/Mês | B38: =D12 -> 58118.158 | C38: Referência | F38: Categoria | G38: Jan-Fev | H38: Mar-Abr | I38: Mai | K38: João Guilherme | L38: =N14 -> #REF!
A39: Comprometimento Fixos | B39: =I20/D12 -> 0.27824808 | C39: Meta: <50% | D39: =IF(B39<0.5,"✅ Saudável",IF(B39<0.7,"⚠️ Atenção","❌ Alto")) -> ✅ Saudável | F39: Cartão | G39: ='janeiro 26'!H6+'fevereiro 26'!H8 -> 19197.46 | H39: ='março 26'!H12+'abril 26'!H6 -> 15380.47 | I39: ='maio 26'!H6 -> 17000 | K39: Ana Luisa | L39: =N15 -> #REF!
A40: Total Investido | B40: =G11 -> 60620 | C40: Crescente | D40: =IF(G11>50000,"✅ Bom","⚠️ Aumentar") -> ✅ Bom | F40: Escola | G40: ='janeiro 26'!H9+'fevereiro 26'!H6 -> 14866.79 | H40: ='março 26'!H6+'abril 26'!H8 -> 16141.55 | I40: ='maio 26'!H8 -> 7206.3 | K40: Luisa Juliana | L40: =N16 -> #REF!
...

Sheet Reembolso Cigna
B1: FUNCIONÁRIO | C1: PACIENTE | D1: PRESTADOR | E1: CNPJ/CPF | F1: TIPO | G1: DATA RECIBO | H1: VALOR | I1: reembolsado | J1: DIFERENÇA | K1: TOTAL REEMBOLSO | L1: COMENTÁRIO CIGNA | M1: DATA ACERTO FOLHA | N1: Nº CLAIM | O1: DOCUMENTO | P1: NOVO Nº CLAIM | Q1: TEXTO RECONSIDERAÇÃO | R1: SITUAÇÃO | S1: Número da NF
B2: LUISA JULIANA FARIA RAMALHO DE SO | C2: Priscila da Silva Herbas Palomo | D2: Wendy Paola Ramirez Molano | E2: 901.505.418-56 | F2: Terapia | G2: 45597 | H2: 840 | I2: FALSE | J2: 840 | K2: - | L2: The maximum benefit for this calendar year has been paid | M2: 45687 | N2: 133099897
B3: LUISA JULIANA FARIA RAMALHO DE SO | C3: Priscila da Silva Herbas Palomo | D3: ICC Clinica de Radiologia | E3: 27.256.678/0001-60 | F3: Outros | G3: 45300 | H3: 60 | I3: TRUE | J3: -0.01 | K3: 60.01 | M3: 45715 | N3: 133971697
B4: LUISA JULIANA FARIA RAMALHO DE SO | C4: Joao Guilherme Ramalho Palomo | D4: Clinica de Pediatria Luna SS Ltda | E4: 592.377.448-89 | F4: Consulta | G4: 45899 | H4: 690 | I4: TRUE | J4: 138 | K4: 552 | M4: 45944 | N4: 136332380
B5: LUISA JULIANA FARIA RAMALHO DE SO | C5: Ana Luisa Ramalho Palomo | D5: Rogério Ribeiro de Sousa | E5: 112.844.728-25 | F5: Terapia | G5: 45716 | H5: 820 | I5: TRUE | J5: 163.84 | K5: 656.16 | M5: 45852 | N5: 134388950
B6: LUISA JULIANA FARIA RAMALHO DE SO | C6: Ana Luisa Ramalho Palomo | D6: Rogério Ribeiro de Souza | E6: 112.844.728-25 | F6: Honorário | G6: 45776 | H6: 850 | I6: TRUE | J6: 169.71 | K6: 680.29 | L6: Please send an itemized bill with future claims | M6: 45835 | N6: 135081986
B7: LUISA JULIANA FARIA RAMALHO DE SO | C7: Luisa Juliana Faria Ramalho de Souza | D7: Wendy Paola Ramirez Molano | E7: 901.505.418-56 | F7: Terapia | G7: 45567 | H7: 640 | I7: TRUE | J7: 128.28 | K7: 511.72 | M7: 45715 | N7: 133981461
B8: LUISA JULIANA FARIA RAMALHO DE SO | C8: Luisa Juliana Faria Ramalho de Souza | D8: Rogério Ribeiro de Sousa | E8: 112.844.728-25 | F8: Terapia | G8: 45685 | H8: 1040 | I8: TRUE | J8: 207.52 | K8: 832.48 | L8: =0 -> 0 | M8: 45965 | N8: 134102446
B9: LUISA JULIANA FARIA RAMALHO DE SO | C9: Priscila da Silva Herbas Palomo | D9: ICC Clinica de Radiologia | E9: 27.256.678/0001-60 | F9: Outros | G9: 45300 | H9: 60 | I9: FALSE | J9: 60 | K9: - | L9: This is a duplicate of a previously processed claim | M9: 45965 | N9: 134112070
B10: LUISA JULIANA FARIA RAMALHO DE SO | C10: Priscila da Silva Herbas Palomo | D10: Saude da Vila - Odontologia | E10: 37.239.181/0001-13 | F10: Outros | G10: 45665 | H10: 1260 | I10: TRUE | J10: 504.03 | K10: 755.97 | L10: Minimum amount paid; itemized bill not received | M10: 45965 | N10: 134112138
B11: LUISA JULIANA FARIA RAMALHO DE SO | C11: Priscila da Silva Herbas Palomo | D11: Saude da Vila - Odontologia | E11: 37.239.181/0001-13 | F11: Outros | G11: 45684 | H11: 580 | I11: TRUE | J11: 231.98 | K11: 348.02 | L11: Minimum amount paid; itemized bill not received | M11: 45965 | N11: 134112198
B12: LUISA JULIANA FARIA RAMALHO DE SO | C12: Luisa Juliana Faria Ramalho de Souza | D12: Rogério Ribeiro de Souza | E12: 112.844.728-25 | F12: Honorário | G12: 45776 | H12: 1200 | I12: TRUE | J12: -0.9 | K12: 1200.9 | L12: Please send an itemized bill with future claims | M12: 45835 | N12: 135081001
B13: LUISA JULIANA FARIA RAMALHO DE SO | C13: Ana Luisa Ramalho Palomo | D13: Humanitas Instituto Integrado de Saud | E13: 14.301.335/0001-54 | F13: Honorário | G13: 45769 | H13: 640 | I13: TRUE | J13: 0.45 | K13: 639.55 | M13: 45835 | N13: 135081985
B14: LUISA JULIANA FARIA RAMALHO DE SO | C14: Luisa Juliana Faria Ramalho de Souza | D14: Wendy Paola Ramirez Molano | E14: 901.505.418-56 | F14: Terapia | G14: 45599 | H14: 840 | I14: TRUE | J14: 168.07 | K14: 671.93 | M14: 45715 | N14: 133981476
B15: LUISA JULIANA FARIA RAMALHO DE SO | C15: Joao Guilherme Ramalho Palomo | D15: Ciresp Cirurgiões especializado sc ltda | E15: 01.183.539/0001-96 | F15: Honorário | G15: 45775 | H15: 850 | I15: FALSE | J15: 850 | K15: - | L15: The maximum frequency limit for this service has been met | M15: 45835 | N15: 135081988 | O15: Dr Ricardo Urologista Pediatra cirurgiao Joao Guilher.pdf | P15: 41072719 | Q15: reconsider the claim for client number ____ and classify it as a Medical Outpatient Physician Visit. | R15: aguardando resposta da cigna
B16: LUISA JULIANA FARIA RAMALHO DE SO | C16: Priscila da Silva Herbas Palomo | D16: Instituto de cirurgia Eduardo Akaishi | E16: 06.287.892/0001-30 | F16: Honorário | G16: 45772 | H16: 700 | I16: TRUE | J16: -0.55 | K16: 700.55 | M16: 45835 | N16: 135123504
B17: LUISA JULIANA FARIA RAMALHO DE SO | C17: Priscila da Silva Herbas Palomo | D17: Espaço Yuan Terapias LTDA. | E17: 54.111.192/0001-32 | F17: Terapia | G17: 45703 | H17: 300 | I17: TRUE | J17: 60 | K17: 240 | M17: 45852 | N17: 134388831
B18: LUISA JULIANA FARIA RAMALHO DE SO | C18: Priscila da Silva Herbas Palomo | D18: TKMO - Instituto Otorrino | E18: 10.234.758/0001-48 | F18: Honorário | G18: 45702 | H18: 700 | I18: TRUE | J18: 140 | K18: 560 | M18: 45852 | N18: 134388832
B19: LUISA JULIANA FARIA RAMALHO DE SO | C19: Luisa Juliana Faria Ramalho de Souza | D19: Wendy Paola Ramirez Molano | E19: 901.505.418-56 | F19: Terapia | G19: 45538 | H19: 500 | I19: TRUE | J19: 100 | K19: 400 | M19: 45715 | N19: 133981491
B20: LUISA JULIANA FARIA RAMALHO DE SO | C20: Luisa Juliana Faria Ramalho de Souza | D20: Rogério Ribeiro de Sousa | E20: 112.844.728-25 | F20: Terapia | G20: 45716 | H20: 1040 | I20: TRUE | J20: 207.79 | K20: 832.21 | M20: 45852 | N20: 134388975
B21: LUISA JULIANA FARIA RAMALHO DE SO | C21: Priscila da Silva Herbas Palomo | D21: Espaço yuan terapias ltda | E21: 54.111.192/0001-32 | F21: Terapia | G21: 45731 | H21: 990 | I21: TRUE | J21: 198.07 | K21: 791.93 | M21: 45852 | N21: 134617047
B22: LUISA JULIANA FARIA RAMALHO DE SO | C22: Ana Luisa Ramalho Palomo | D22: Humanitas Instituto Integrado de Saud | E22: 14.301.335/0001-54 | F22: Honorário | G22: 45728 | H22: 640 | I22: TRUE | J22: -0.02 | K22: 640.02 | M22: 45852 | N22: 134632390
B23: LUISA JULIANA FARIA RAMALHO DE SO | C23: Luisa Juliana Faria Ramalho de Souza | D23: Wendy Paola Ramirez Molano | E23: 901.505.418-56 | F23: Terapia | G23: 45629 | H23: 640 | I23: TRUE | J23: 127.83 | K23: 512.17 | M23: 45715 | N23: 133981505
B24: LUISA JULIANA FARIA RAMALHO DE SO | C24: Joao Guilherme Ramalho Palomo | D24: Humanitas Instituto Integrado de Saud | E24: 14.301.335/0001-54 | F24: Honorário | G24: 45728 | H24: 640 | I24: TRUE | J24: -0.02 | K24: 640.02 | M24: 45852 | N24: 134632639
B25: LUISA JULIANA FARIA RAMALHO DE SO | C25: Joao Guilherme Ramalho Palomo | D25: Wendy Paola Ramírez Molano | E25: 901.505.418-56 | F25: Terapia | G25: 45725 | H25: 688 | I25: TRUE | J25: 137.79 | K25: 550.21 | M25: 45852 | N25: 134632534
B26: LUISA JULIANA FARIA RAMALHO DE SO | C26: Luisa Juliana Faria Ramalho de Souza | D26: Instituto de Cirurgia Eduardo Akaishi | E26: 06.287.892/0001-30 | F26: Consulta | G26: 45901 | H26: 700 | I26: TRUE | J26: -0.01 | K26: 700.01 | M26: 45944 | N26: 136332485
B27: LUISA JULIANA FARIA RAMALHO DE SO | C27: Priscila da Silva Herbas Palomo | D27: KARINE SAITO PSICOLOGIA LTDA | E27: 49.361.486/0001-82 | F27: Consulta | G27: 45916 | H27: 5600 | I27: TRUE | J27: 0.02 | K27: 5599.98 | M27: 45944 | N27: 136476032
... B32: LUISA JULIANA FARIA RAMALHO DE SO | C32: Luisa Juliana Faria Ramalho de Souza | D32: LUCE E SANTOS SERVICOS MEDICOS LT | E32: 32.537.887/0001-48 | F32: Consulta | G32: 45940 | H32: 500 | I32: TRUE | J32: 99.97 | K32: 400.03 | M32: 45988 | N32: 136785632
B33: LUISA JULIANA FARIA RAMALHO DE SO | C33: Luisa Juliana Faria Ramalho de Souza | D33: LUCE E SANTOS SERVICOS MEDICOS LT | E33: 32.537.887/0001-48 | F33: Consulta | G33: 45940 | H33: 450 | I33: TRUE | J33: 90 | K33: 360 | L33: Coverage based on info received; service description missing | M33: 45988 | N33: 136785637
B34: LUISA JULIANA FARIA RAMALHO DE SO | C34: Ana Luisa Ramalho Palomo | D34: Alvo Clínica Médica S/S | E34: 31.030.262/0001-22 | F34: Consulta | G34: 45965 | H34: 800 | I34: TRUE | J34: -0.02 | K34: 800.02 | M34: 45988 | N34: 137073548
B35: LUISA JULIANA FARIA RAMALHO DE SO | C35: Priscila da Silva Herbas Palomo | D35: SOCIEDADE BENEF ISRAELITABRAS HOS | E35: 60.765.823/0039-02 | F35: Consulta | G35: 45818 | H35: 576.06 | I35: FALSE | J35: 576 | K35: 0.06 | L35: This is a duplicate of a previously processed claim | M35: 45988 | N35: 137073552
B36: LUISA JULIANA FARIA RAMALHO DE SO | C36: Priscila da Silva Herbas Palomo | D36: SOCIEDADE BENEF ISRAELITABRAS HOS | E36: 60.765.823/0012-92 | F36: Consulta | G36: 45848 | H36: 1107.63 | I36: TRUE | J36: 221.51 | K36: 886.12 | M36: 45988 | N36: 137073556
B37: LUISA JULIANA FARIA RAMALHO DE SO | C37: Priscila da Silva Herbas Palomo | D37: KARINE SAITO PSICOLOGIA LTDA | E37: 49.361.486/0001-82 | F37: Consulta | G37: 45961 | H37: 3200 | I37: TRUE | J37: 0.02 | K37: 3199.98 | L37: Please send an itemized bill with future claims | M37: 45988 | N37: 137073557
B38: LUISA JULIANA FARIA RAMALHO DE SO | C38: Joao Guilherme Ramalho Palomo | D38: Wendy Paola Ramírez Molano | E38: 901.505.418-56 | F38: Consulta | G38: 45931 | H38: 688 | I38: TRUE | J38: 137.55 | K38: 550.45 | M38: 45988 | N38: 137076305
B39: LUISA JULIANA FARIA RAMALHO DE SO | C39: Joao Guilherme Ramalho Palomo | D39: Alvo Clínica Médica S/S | E39: 31.030.262/0001-22 | F39: Consulta | G39: 45965 | H39: 800 | I39: FALSE | J39: 799.95 | K39: 0.05 | M39: 45988 | N39: 137076320 | O39: Dr. Andre Luis para Joao Guilherme.pdf | P39: 41073117 | Q39: reconsider the claim for client number ____ and classify it as a Medical Outpatient Physician Visit. | R39: aguardando resposta da cigna | S39: 6344
B40: LUISA JULIANA FARIA RAMALHO DE SO | C40: Joao Guilherme Ramalho Palomo | D40: Alvo Clínica Médica S/S | E40: 31.030.262/0001-22 | F40: Consulta | G40: 45965 | H40: 800 | I40: FALSE | M40: 46271 | N40: 41073117 | O40: Dr. Andre Luis para Joao Guilherme.pdf | R40: enviado ao HR | S40: 6344
B41: LUISA JULIANA FARIA RAMALHO DE SO | C41: Joao Guilherme Ramalho Palomo | D41: Ciresp Cirurgiões especializado sc ltda | E41: 01.183.539/0001-96 | F41: Honorário | G41: 45775 | H41: 850 | I41: FALSE | M41: 46182 | N41: 41072719 | O41: Dr Ricardo Urologista Pediatra cirurgiao Joao Guilher | R41: enviado ao HR | S41: 709
B42: 2026
B43: LUISA JULIANA FARIA RAMALHO DE SOUZA | C43: João Guilherme Ramalho Palomo | D43: MCAVALCANTECOSTA CONSULTAS EXAMES E CONSULTORIA MEDICA LTDA | E43: 41.571.578/0001-85 | F43: Consulta | G43: 46093 | H43: 500 | I43: TRUE | J43: 0,01 | K43: 499,99 | M43: 16/04/2026 | N43: 138499716
B44: LUISA JULIANA FARIA RAMALHO DE SOUZA | C44: Priscila da Silva Herbas Palomo | D44: Espaço yuan terapias ltda | E44: 54111192000132 | F44: Consulta | G44: 45942 | H44: 520 | I44: TRUE | J44: 103,95 | K44: 416,05 | M44: 16/04/2026 | N44: 136807011
...

Sheet Escola crianças
C2: Roda viva | H2: Oliver
C3: 46024 | D3: 3300.54 | E3: 6600.22 | H3: 46024 | I3: 4922 | J3: 4922 | K3: =SUM(J4+I3) -> 9844
C4: 46036 | D4: 946 | E4: 6600.22 | H4: 46036 | I4: 4922 | J4: 4922 | K4: =SUM(J5+I4) -> 9844
C5: 46053 | D5: 118.36 | E5: 6600.22 | H5: 46053 | I5: 4922 | J5: 4922 | K5: =SUM(J6+I5) -> 9844
C6: 46056 | D6: 6600.22 | E6: 6600.22 | H6: 46056 | I6: 4922 | J6: 4922 | K6: =SUM(J7+I6) -> 9844
C7: 46086 | D7: 6663.84 | E7: 6600.22 | H7: 46086 | I7: 4922 | J7: 4922 | K7: =SUM(J8+I7) -> 9844
C8: 46113 | D8: 6600.22 | E8: 6600.22 | H8: 46113 | I8: 4922 | J8: 4922 | K8: =SUM(J9+I8) -> 9844
C9: 46144 | D9: 6600.22 | E9: 6600.22 | H9: 46144 | I9: 4922 | J9: 4922 | K9: =SUM(J10+I9) -> 9844
C10: 46175 | D10: 6600.22 | E10: 6600.22 | H10: 46175 | I10: 4922 | J10: 4922 | K10: =SUM(J11+I10) -> 9844
C11: 46186 | D11: 280 | E11: 6600.22 | H11: 46186 | I11: 4922 | J11: 4922 | K11: =SUM(J12+I11) -> 9844
C12: 46190 | D12: 3365 | E12: 6600.22 | H12: 46190 | I12: 4922 | J12: 4922 | K12: =SUM(J13+I12) -> 9844
C13: 46204 | D13: 6600.22 | E13: 6600.22 | H13: 46204 | I13: 4922 | J13: 4922 | K13: =SUM(J14+I13) -> 9844
C14: 46233 | D14: 967.8 | E14: 6600.22 | H14: 46233 | I14: 4922 | J14: 4922 | K14: =SUM(J15+I14) -> 9844
... C21: 46357 | D21: 6600.22 | E21: 6600.22 | H21: 46357 | I21: 4922 | J21: 4922 | K21: =SUM(J22+I21) -> 9844
C22: 05/dec | D22: 2242 | E22: 6600.22 | H22: 05/dec | I22: 4922 | J22: 4922 | K22: 9844
C23: Total por 2 | D23: =SUM(D3:D22)/2 -> 43242.87 | E23: =SUM(E3:E22) -> 132004.4 | H23: Total por 2 | K23: =SUM(K3:K22) -> 196880

Sheet janeiro 26
A1: 📊 EXTRATO BANCÁRIO - JANEIRO/2026
A2: Conta: Ag 3767 | CC 29709-0 | Itaú Personnalité
A4: 📈 RESUMO DO MÊS | G4: 📊 ANÁLISE POR CATEGORIA
A5: Saldo Inicial (31/12) | B5: 5021.19 | G5: Categoria | H5: Saídas (R$) | I5: % do Total
A6: Saldo Final C/C | B6: 1 | G6: Cartão | H6: =SUMIF($E$13:$E$59,"Cartão",$D$13:$D$59) -> 16607.75 | I6: =IF($D$63>0,H6/$D$63,0) -> 0.18961186
A7: Saldo Aplic Aut Mais | B7: 13240.28 | G7: Financiamento | H7: =SUMIF($E$13:$E$59,"Financiamento",$D$13:$D$59) -> 6404.66 | I7: =IF($D$63>0,H7/$D$63,0) -> 0.073122457
A8: Saldo Final Total | B8: 13241.28 | G8: Transferência | H8: =SUMIF($E$13:$E$59,"Transferência",$D$13:$D$59) -> 7521.28 | I8: =IF($D$63>0,H8/$D$63,0) -> 0.085870987
A9: Saldo Poupança | B9: 65237.17 | G9: Escola | H9: =SUMIF($E$13:$E$59,"Escola",$D$13:$D$59) -> 3788.01 | I9: =IF($D$63>0,H9/$D$63,0) -> 0.043247979
A10: Total Investimentos | B10: 65237.17 | G10: Terapia/Psicologia | H10: =SUMIF($E$13:$E$59,"Terapia/Psicologia",$D$13:$D$59) -> 4000 | I10: =IF($D$63>0,H10/$D$63,0) -> 0.045668283
G11: Serviços | H11: =SUMIF($E$13:$E$59,"Serviços",$D$13:$D$59) -> 920 | I11: =IF($D$63>0,H11/$D$63,0) -> 0.010503705
A12: Data | B12: Descrição | C12: Entradas (R$) | D12: Saídas (R$) | E12: Categoria | G12: Telefone | H12: =SUMIF($E$13:$E$59,"Telefone",$D$13:$D$59) -> 82.13 | I12: =IF($D$63>0,H12/$D$63,0) -> 0.00093768403
A13: 46054 | B13: PIX QRS CIRANDA BER | D13: 2499.88 | E13: Transferência | G13: Internet/TV | H13: =SUMIF($E$13:$E$59,"Internet/TV",$D$13:$D$59) -> 323.87 | I13: =IF($D$63>0,H13/$D$63,0) -> 0.0036976467
A14: 46054 | B14: PIX TRANSF Ana Cam | D14: 248 | E14: Transferência | G14: Conta Luz | H14: =SUMIF($E$13:$E$59,"Conta Luz",$D$13:$D$59) -> 327.82 | I14: =IF($D$63>0,H14/$D$63,0) -> 0.0037427442
A15: 46054 | B15: Cartão Personnalité | D15: 61.7 | E15: Cartão | G15: Farmácia | H15: =SUMIF($E$13:$E$59,"Farmácia",$D$13:$D$59) -> 303.84 | I15: =IF($D$63>0,H15/$D$63,0) -> 0.0034689628
A16: 46054 | B16: Pers Black 3608-7306 | D16: 16546.05 | E16: Cartão | G16: Seguro | H16: =SUMIF($E$13:$E$59,"Seguro",$D$13:$D$59) -> 105.48 | I16: =IF($D$63>0,H16/$D$63,0) -> 0.0012042726
A17: 46054 | B17: TBI Poupança | C17: 15000 | E17: Transferência Interna | G17: Compras | H17: =SUMIF($E$13:$E$59,"Compras",$D$13:$D$59) -> 979.85 | I17: =IF($D$63>0,H17/$D$63,0) -> 0.011187017
A18: 46054 | B18: DA ELETROPAULO | D18: 327.82 | E18: Conta Luz | G18: Alimentação | H18: =SUMIF($E$13:$E$59,"Alimentação",$D$13:$D$59) -> 232.84 | I18: =IF($D$63>0,H18/$D$63,0) -> 0.0026583508
A19: 46143 | B19: INT Pag Tít 237 | D19: 490.61 | E19: Pagamento | G19: Pagamento | H19: =SUMIF($E$13:$E$59,"Pagamento",$D$13:$D$59) -> 490.61 | I19: =IF($D$63>0,H19/$D$63,0) -> 0.0056013291
A20: 46143 | B20: VIVO-SP | D20: 82.13 | E20: Telefone | G20: TOTAL SAÍDAS | H20: =SUM(H6:H19) -> 42088.14 | I20: =SUM(I6:I19) -> 0.48052328
A21: 46143 | B21: PIX QRS AMAZON | D21: 81.07 | E21: Compras
A22: 46143 | B22: PIX TRANSF MARCIA | D22: 1540 | E22: Transferência | G22: 💰 ENTRADAS
A23: 46143 | B23: TBI Poupança | C23: 5000 | E23: Transferência Interna | G23: Categoria | H23: Valor (R$)
A24: 46143 | B24: PIX TRANSF PRISCILA | C24: 3790 | E24: Recebimento | G24: Salário | H24: =SUMIF($E$13:$E$59,"Salário",$C$13:$C$59) -> 62537.38
A25: 46143 | B25: DA CLARO | D25: 323.87 | E25: Internet/TV | G25: Recebimento (PIX Priscila) | H25: =SUMIF($E$13:$E$59,"Recebimento",$C$13:$C$59) -> 8675
A26: 46174 | B26: PIX TRANSF BABY VI | D26: 800 | E26: Transferência | G26: Reembolso McKinsey | H26: =SUMIF($E$13:$E$59,"Reembolso",$C$13:$C$59) -> 391.61
A27: 46174 | B27: TED McKINSEY | C27: 151.27 | E27: Reembolso | G27: Transf. Interna (Poupança) | H27: =SUMIF($E$13:$E$59,"Transferência Interna",$C$13:$C$59) -> 23400
A28: 46204 | B28: PIX QRS RAIA DROGASIL | D28: 303.84 | E28: Farmácia | G28: Devolução | H28: =SUMIF($E$13:$E$59,"Devolução",$C$13:$C$59) -> 93.82
A29: 46204 | B29: PIX TRANSF MARCIA | D29: 440 | E29: Transferência
A30: 46204 | B30: PIX TRANSF SABRINA | D30: 51 | E30: Transferência
A31: 46266 | B31: PIX QRS CASA SANTO | D31: 115.99 | E31: Compras
A32: 46266 | B32: PIX TRANSF NATHALI | D32: 977.4 | E32: Transferência
A33: 46266 | B33: TED McKINSEY | C33: 240.34 | E33: Reembolso
A34: 46357 | B34: INT Pag Tít (Escola) | D34: 2757.01 | E34: Escola
A35: 46357 | B35: PIX QRS Pagar Me | D35: 61.39 | E35: Compras
A36: 46357 | B36: PIX TRANSF MARIANA | C36: 35 | E36: Recebimento
A37: 46357 | B37: PIX TRANSF PRISCILA | C37: 3000 | E37: Recebimento
A38: 15/01 | B38: Financ Imobiliário 034 | D38: 6404.66 | E38: Financiamento
A39: 15/01 | B39: TBI Poupança | C39: 3000 | E39: Transferência Interna
A40: 15/01 | B40: DEV PIX Marketp | C40: 93.82 | E40: Devolução
A41: 15/01 | B41: PIX TRANSF PRISCILA | C41: 200 | E41: Recebimento
...

Sheet março 26
A1: 📊 EXTRATO BANCÁRIO - MARÇO/2026
A2: Conta: Ag 3767 | CC 29709-0 | Itaú Personnalité
A4: 📈 RESUMO DO MÊS | G4: 📊 ANÁLISE POR CATEGORIA
A5: Saldo Inicial (28/02) | B5: 1525.05 | G5: Categoria | H5: Saídas (R$) | I5: % do Total
A6: Saldo Final C/C | B6: 1 | G6: Escola | H6: =SUMIF($E$11:$E$75,"Escola",$D$11:$D$75) -> 13800.6 | I6: =H6/$D$78 -> 0.15885521
A7: Saldo Aplic Aut Mais | B7: 20655.2 | G7: Financiamento | H7: =SUMIF($E$11:$E$75,"Financiamento",$D$11:$D$75) -> 6398.09 | I7: =H7/$D$78 -> 0.073646791
A8: Saldo Final Total | B8: 20656.2 | G8: Investimento | H8: =SUMIF($E$11:$E$75,"Investimento",$D$11:$D$75) -> 42620 | I8: =H8/$D$78 -> 0.49058801
G9: Transferência | H9: =SUMIF($E$11:$E$75,"Transferência",$D$11:$D$75) -> 9446.99 | I9: =H9/$D$78 -> 0.10874191
A10: Data | B10: Descrição | C10: Entradas (R$) | D10: Saídas (R$) | E10: Categoria | G10: Transferência Interna | H10: =SUMIF($E$11:$E$75,"Transferência Interna",$D$11:$D$75) -> 3000 | I10: =H10/$D$78 -> 0.034532239
A11: 46056 | B11: PIX QRS CIRANDA BER (Escola) | D11: 6900.3 | E11: Escola | G11: Condomínio | H11: =SUMIF($E$11:$E$75,"Condomínio",$D$11:$D$75) -> 2290.55 | I11: =H11/$D$78 -> 0.02636594
A12: 46056 | B12: PIX TRANSF MARIANA | D12: 60 | E12: Transferência | G12: Cartão | H12: =SUMIF($E$11:$E$75,"Cartão",$D$11:$D$75) -> 1660.06 | I12: =H12/$D$78 -> 0.01910853
A13: 46056 | B13: Aplicação COFRINHOS | D13: 7220 | E13: Investimento | G13: Compras | H13: =SUMIF($E$11:$E$75,"Compras",$D$11:$D$75) -> 2764.33 | I13: =H13/$D$78 -> 0.031819501
A14: 46056 | B14: Aplicação COFRINHOS | D14: 35400 | E14: Investimento | G14: Pagamento | H14: =SUMIF($E$11:$E$75,"Pagamento",$D$11:$D$75) -> 3270.58 | I14: =H14/$D$78 -> 0.037646817
A15: 46056 | B15: Cartão Personnalité | D15: 485.89 | E15: Cartão | G15: IPTU | H15: =SUMIF($E$11:$E$75,"IPTU",$D$11:$D$75) -> 766.06 | I15: =H15/$D$78 -> 0.0088179223
A16: 46056 | B16: Pers Black 3608-7306 | D16: 1174.17 | E16: Cartão | G16: Internet/TV | H16: =SUMIF($E$11:$E$75,"Internet/TV",$D$11:$D$75) -> 321.01 | I16: =H16/$D$78 -> 0.0036950647
A17: 46056 | B17: TBI Poupança | C17: 35400 | E17: Transferência Interna | G17: Conta Luz | H17: =SUMIF($E$11:$E$75,"Conta Luz",$D$11:$D$75) -> 360.61 | I17: =H17/$D$78 -> 0.0041508902
A18: 46056 | B18: TBI Poupança (rendimento) | C18: 0.58 | E18: Rendimento | G18: Seguro | H18: =SUMIF($E$11:$E$75,"Seguro",$D$11:$D$75) -> 105.48 | I18: =H18/$D$78 -> 0.0012141535
A19: 46056 | B19: TBI Poupança | C19: 18000 | E19: Transferência Interna | G19: Estacionamento | H19: =SUMIF($E$11:$E$75,"Estacionamento",$D$11:$D$75) -> 43 | I19: =H19/$D$78 -> 0.00049496209
A20: 46056 | B20: TBI Poupança | C20: 7000 | E20: Transferência Interna | G20: Transporte | H20: =SUMIF($E$11:$E$75,"Transporte",$D$11:$D$75) -> 27.98 | I20: =H20/$D$78 -> 0.00032207068
A21: 46056 | B21: DA ELETROPAULO | D21: 360.61 | E21: Conta Luz | G21: TOTAL SAÍDAS | H21: =SUM(H6:H20) -> 86875.34 | I21: =SUM(I6:I20) -> 1
A22: 46084 | B22: PAG BOLETO CONDOMINIO | D22: 2290.55 | E22: Condomínio
A23: 46115 | B23: PIX TRANSF PRISCILA | C23: 6000 | E23: Recebimento | G23: 💰 ENTRADAS
A24: 46145 | B24: PIX TRANSF MEL NIG | D24: 100 | E24: Transferência | G24: Categoria | H24: Valor (R$)
A25: 46145 | B25: PIX TRANSF PRISCILA | C25: 3300 | E25: Recebimento | G25: Salário | H25: =SUMIF($E$11:$E$75,"Salário",$C$11:$C$75) -> 19749.56
A26: 46145 | B26: DA CLARO | D26: 321.01 | E26: Internet/TV | G26: Recebimento (PIX Priscila e outros) | H26: =SUMIF($E$11:$E$75,"Recebimento",$C$11:$C$75) -> 19320.5
A27: 46268 | B27: PIX QRS SECRETARIA (IPTU) | D27: 766.06 | E27: IPTU | G27: Reembolso McKinsey | H27: =SUMIF($E$11:$E$75,"Reembolso",$C$11:$C$75) -> 3171.58
A28: 46268 | B28: PIX QRS SHPP BRASIL | D28: 87.03 | E28: Compras | G28: Transferência Interna (Poupança) | H28: =SUMIF($E$11:$E$75,"Transferência Interna",$C$11:$C$75) -> 63400
A29: 46268 | B29: PIX TRANSF BARBARA | C29: 74 | E29: Recebimento | G29: Devolução | H29: =SUMIF($E$11:$E$75,"Devolução",$C$11:$C$75) -> 363.64
A30: 46268 | B30: PIX TRANSF MARIANA | C30: 118 | E30: Recebimento | G30: Rendimento | H30: =SUMIF($E$11:$E$75,"Rendimento",$C$11:$C$75) -> 0.58
A31: 46268 | B31: PIX TRANSF PRISCILA | C31: 1290 | E31: Recebimento | G31: TOTAL ENTRADAS | H31: =SUM(H25:H30) -> 106005.86
A32: 46268 | B32: PIX TRANSF SABRINA | C32: 48 | E32: Recebimento
A33: 46329 | B33: PIX TRANSF FABIANE | D33: 1400 | E33: Transferência
A34: 46329 | B34: PIX TRANSF PATRICIA | C34: 74 | E34: Recebimento
A35: 46359 | B35: PIX QRS SHPP BRASIL | D35: 426.48 | E35: Compras
A36: 13/03 | B36: PIX QRS ZOOP BRASIL | D36: 363.64 | E36: Compras
A37: 14/03 | B37: PIX QRS G1 ESTACION | D37: 43 | E37: Estacionamento
A38: 14/03 | B38: PIX TRANSF PRISCILA | C38: 3130 | E38: Recebimento
A39: 16/03 | B39: Lançamento a Débito | D39: 6398.09 | E39: Financiamento
A40: 16/03 | B40: PIX QRS 53.946.366 | D40: 1175.8 | E40: Compras
A41: 16/03 | B41: PIX TRANSF MARCIA | D41: 1980 | E41: Transferência
...

Sheet fevereiro 26
A1: 📊 EXTRATO BANCÁRIO - FEVEREIRO/2026
A2: Conta: Ag 3767 | CC 29709-0 | Itaú Personnalité
A4: 📈 RESUMO DO MÊS | G4: 📊 ANÁLISE POR CATEGORIA
A5: Saldo Inicial (31/01) | B5: 13241.28 | G5: Categoria | H5: Saídas (R$) | I5: % do Total
A6: Saldo Final C/C | B6: 1 | G6: Escola | H6: =SUMIF($E$12:$E$81,"Escola",$D$12:$D$81) -> 11078.78 | I6: =H6/$D$84 -> 0.33891711
A7: Saldo Aplic Aut Mais | B7: 1524.05 | G7: Financiamento | H7: =SUMIF($E$12:$E$81,"Financiamento",$D$12:$D$81) -> 6403.15 | I7: =H7/$D$84 -> 0.19588232
A8: Saldo Final Total | B8: 1525.05 | G8: Cartão | H8: =SUMIF($E$12:$E$81,"Cartão",$D$12:$D$81) -> 2589.71 | I8: =H8/$D$84 -> 0.079223256
A9: Saldo Poupança | B9: 60132.65 | G9: Transferência | H9: =SUMIF($E$12:$E$81,"Transferência",$D$12:$D$81) -> 3587 | I9: =H9/$D$84 -> 0.10973191
G10: Transferência Interna | H10: =SUMIF($E$12:$E$81,"Transferência Interna",$D$12:$D$81) -> 2964 | I10: =H10/$D$84 -> 0.090673369
A11: Data | B11: Descrição | C11: Entradas (R$) | D11: Saídas (R$) | E11: Categoria | G11: Compras | H11: =SUMIF($E$12:$E$81,"Compras",$D$12:$D$81) -> 1757.1 | I11: =H11/$D$84 -> 0.053752421
A12: 46055 | B12: TBI Poupança | D12: 2000 | E12: Transferência Interna | G12: Terapia | H12: =SUMIF($E$12:$E$81,"Terapia",$D$12:$D$81) -> 610 | I12: =H12/$D$84 -> 0.018660849
A13: 46055 | B13: PAY -ALO B | D13: 84.73 | E13: Compras | G13: Alimentação | H13: =SUMIF($E$12:$E$81,"Alimentação",$D$12:$D$81) -> 786.29 | I13: =H13/$D$84 -> 0.024053834
A14: 46055 | B14: PAY -KALUN | D14: 299.16 | E14: Compras | G14: Lazer | H14: =SUMIF($E$12:$E$81,"Lazer",$D$12:$D$81) -> 578.13 | I14: =H14/$D$84 -> 0.017685896
A15: 46055 | B15: PIX QRS AKI MERCADO | D15: 24.93 | E15: Alimentação | G15: IPTU | H15: =SUMIF($E$12:$E$81,"IPTU",$D$12:$D$81) -> 766.06 | I15: =H15/$D$84 -> 0.023434967
A16: 46055 | B16: PIX QRS CIRANDA BER (Escola) | D16: 8800.48 | E16: Escola | G16: Internet/TV | H16: =SUMIF($E$12:$E$81,"Internet/TV",$D$12:$D$81) -> 323.87 | I16: =H16/$D$84 -> 0.0099076869
A17: 46055 | B17: Cartão Personnalité | D17: 347.45 | E17: Cartão | G17: Conta Luz | H17: =SUMIF($E$12:$E$81,"Conta Luz",$D$12:$D$81) -> 451.49 | I17: =H17/$D$84 -> 0.013811781
A18: 46055 | B18: Pers Black 3608-7306 | D18: 2242.26 | E18: Cartão | G18: Pagamento | H18: =SUMIF($E$12:$E$81,"Pagamento",$D$12:$D$81) -> 233.59 | I18: =H18/$D$84 -> 0.0071458813
A19: 46055 | B19: PIX TRANSF PRISCILA | C19: 1400 | E19: Recebimento | G19: Telefone | H19: =SUMIF($E$12:$E$81,"Telefone",$D$12:$D$81) -> 85.2 | I19: =H19/$D$84 -> 0.0026064005
A20: 46055 | B20: PIX TRANSF PRISCILA | C20: 400 | E20: Recebimento | G20: Farmácia | H20: =SUMIF($E$12:$E$81,"Farmácia",$D$12:$D$81) -> 143.91 | I20: =H20/$D$84 -> 0.0044024307
A21: 46055 | B21: PIX TRANSF PRISCILA | C21: 1800 | E21: Recebimento | G21: Assinatura | H21: =SUMIF($E$12:$E$81,"Assinatura",$D$12:$D$81) -> 150 | I21: =H21/$D$84 -> 0.0045887333
A22: 46055 | B22: PIX TRANSF PRISCILA | C22: 2400 | E22: Recebimento | G22: Seguro | H22: =SUMIF($E$12:$E$81,"Seguro",$D$12:$D$81) -> 105.48 | I22: =H22/$D$84 -> 0.0032267972
A23: 46055 | B23: DA ELETROPAULO | D23: 451.49 | E23: Conta Luz | G23: Saúde | H23: =SUMIF($E$12:$E$81,"Saúde",$D$12:$D$81) -> 48 | I23: =H23/$D$84 -> 0.0014683946
A24: 46083 | B24: PIX TRANSF PRISCILA | C24: 1880 | E24: Recebimento | G24: Transporte | H24: =SUMIF($E$12:$E$81,"Transporte",$D$12:$D$81) -> 27 | I24: =H24/$D$84 -> 0.00082597199
A25: 46114 | B25: INT Pag Tít 237 | D25: 233.59 | E25: Pagamento | G25: TOTAL SAÍDAS | H25: =SUM(H6:H24) -> 32688.76 | I25: =SUM(I6:I24) -> 1
A26: 46114 | B26: PIX QRS ROGERIO RIB (Terapia) | D26: 340 | E26: Terapia
A27: 46114 | B27: PIX TRANSF LUIS RI | D27: 690 | E27: Transferência | G27: 💰 ENTRADAS
A28: 46144 | B28: PIX QRS ICC (Exame) | D28: 48 | E28: Saúde | G28: Categoria | H28: Valor (R$)
A29: 46144 | B29: PIX QRS JOAO KOBASH | D29: 32 | E29: Compras | G29: Salário | H29: =SUMIF($E$12:$E$81,"Salário",$C$12:$C$81) -> 1249.79
A30: 46144 | B30: PIX QRS JORGE YUKIH | D30: 26 | E30: Compras | G30: Recebimento | H30: =SUMIF($E$12:$E$81,"Recebimento",$C$12:$C$81) -> 11288
A31: 46144 | B31: PIX QRS Odair Domin | D31: 24 | E31: Compras | G31: Reembolso | H31: =SUMIF($E$12:$E$81,"Reembolso",$C$12:$C$81) -> 1197.31
A32: 46144 | B32: PIX TRANSF KATHIAN | D32: 200 | E32: Transferência | G32: Transferência Interna | H32: =SUMIF($E$12:$E$81,"Transferência Interna",$C$12:$C$81) -> 7237.17
A33: 46144 | B33: PIX TRANSF MARCIA | D33: 1760 | E33: Transferência | G33: TOTAL ENTRADAS | H33: =SUM(H29:H32) -> 20972.27
A34: 46144 | B34: PIX TRANSF NELIANE | C34: 260 | E34: Recebimento
A35: 46144 | B35: PIX TRANSF PRISCILA | C35: 1500 | E35: Recebimento
A36: 46144 | B36: TED McKINSEY | C36: 273.59 | E36: Reembolso
A37: 46144 | B37: DA CLARO | D37: 323.87 | E37: Internet/TV
A38: 46175 | B38: PIX TRANSF ESPACO (Terapia) | D38: 270 | E38: Terapia
A39: 46175 | B39: PIX TRANSF MARCIA | D39: 220 | E39: Transferência
A40: 46267 | B40: Int /PM SAO PAU (IPTU) | D40: 766.06 | E40: IPTU
A41: 46297 | B41: INT Pag Tít (Escola) | D41: 2278.3 | E41: Escola
...

Sheet abril 26
A1: 📊 EXTRATO BANCÁRIO - ABRIL/2026
A2: Conta: Ag 3767 | CC 29709-0 | Itaú Personnalité
A4: 📈 RESUMO DO MÊS | G4: 📊 ANÁLISE POR CATEGORIA
A5: Saldo Inicial (31/03) | B5: 20656.2 | G5: Categoria | H5: Saídas (R$) | I5: % do Total
A6: Saldo Final C/C | B6: 1 | G6: Cartão | H6: =SUMIF($E$12:$E$58,"Cartão",$D$12:$D$58) -> 13720.41 | I6: =H6/$H$21 -> 0.42077196
A7: Saldo Aplic Aut Mais | B7: 26010.36 | G7: Financiamento | H7: =SUMIF($E$12:$E$58,"Financiamento",$D$12:$D$58) -> 6404.82 | I7: =H7/$H$21 -> 0.19642042
A8: Saldo Final Total | B8: 26011.36 | G8: Condomínio | H8: =SUMIF($E$12:$E$58,"Condomínio",$D$12:$D$58) -> 2340.95 | I8: =H8/$H$21 -> 0.071791303
A9: Investimentos (CDB Metas) | B9: 44369.62 | G9: Terapia | H9: =SUMIF($E$12:$E$58,"Terapia",$D$12:$D$58) -> 3380 | I9: =H9/$H$21 -> 0.10365647
G10: Transferência | H10: =SUMIF($E$12:$E$58,"Transferência",$D$12:$D$58) -> 1371.5 | I10: =H10/$H$21 -> 0.042060605
A11: Data | B11: Descrição | C11: Entradas (R$) | D11: Saídas (R$) | E11: Categoria | G11: Farmácia | H11: =SUMIF($E$12:$E$58,"Farmácia",$D$12:$D$58) -> 984.2 | I11: =H11/$H$21 -> 0.030183046
A12: 46026 | B12: PIX QRS AMAZON | D12: 58.49 | E12: Compras | G12: Pagamento | H12: =SUMIF($E$12:$E$58,"Pagamento",$D$12:$D$58) -> 1237.05 | I12: =H12/$H$21 -> 0.037937347
A13: 46026 | B13: PIX TRANSF KARINE (Terapia) | D13: 3200 | E13: Terapia | G13: Investimento | H13: =SUMIF($E$12:$E$58,"Investimento",$D$12:$D$58) -> 1000 | I13: =H13/$H$21 -> 0.030667594
A14: 46026 | B14: PIX TRANSF LUCIANA | D14: 50 | E14: Transferência | G14: IPTU | H14: =SUMIF($E$12:$E$58,"IPTU",$D$12:$D$58) -> 766.06 | I14: =H14/$H$21 -> 0.023493217
A15: 46026 | B15: Cartão Personnalité | D15: 206.39 | E15: Cartão | G15: Compras | H15: =SUMIF($E$12:$E$58,"Compras",$D$12:$D$58) -> 420.13 | I15: =H15/$H$21 -> 0.012884376
A16: 46026 | B16: Pers Black 3608-7306 | D16: 13514.02 | E16: Cartão | G16: Internet/TV | H16: =SUMIF($E$12:$E$58,"Internet/TV",$D$12:$D$58) -> 323.87 | I16: =H16/$H$21 -> 0.0099323136
A17: 46026 | B17: TED McKINSEY | C17: 99 | E17: Reembolso | G17: Conta Luz | H17: =SUMIF($E$12:$E$58,"Conta Luz",$D$12:$D$58) -> 334.46 | I17: =H17/$H$21 -> 0.010257083
A18: 46057 | B18: DA ELETROPAULO | D18: 334.46 | E18: Conta Luz | G18: Escola | H18: =SUMIF($E$12:$E$58,"Escola",$D$12:$D$58) -> 193 | I18: =H18/$H$21 -> 0.0059188456
A19: 46146 | B19: PIX TRANSF PRISCILA | C19: 2600 | E19: Recebimento | G19: Transporte | H19: =SUMIF($E$12:$E$58,"Transporte",$D$12:$D$58) -> 25.78 | I19: =H19/$H$21 -> 0.00079061056
A20: 46177 | B20: PIX TRANSF PRISCILA | C20: 2200 | E20: Recebimento | G20: Seguro | H20: =SUMIF($E$12:$E$58,"Seguro",$D$12:$D$58) -> 105.48 | I20: =H20/$H$21 -> 0.0032348178
A21: 46177 | B21: PAG BOLETO CONDOMÍNIO | D21: 2340.95 | E21: Condomínio | G21: TOTAL SAÍDAS | H21: =SUM(H6:H20) -> 32607.71 | I21: 1
A22: 46177 | B22: DA CLARO | D22: 323.87 | E22: Internet/TV | G22: 💰 ENTRADAS
A23: 46207 | B23: PIX TRANSF LUCIANA | D23: 89 | E23: Transferência | G23: 💰 ENTRADAS
A24: 46207 | B24: PIX TRANSF PRISCILA | C24: 2000 | E24: Recebimento | G24: Categoria | H24: Valor (R$)
A25: 46207 | B25: PIX TRANSF PRISCILA | C25: 400 | E25: Recebimento | G25: Salário | H25: =SUMIF($E$12:$E$58,"Salário",$C$12:$C$58) -> 21529.82
A26: 46238 | B26: PIX QRS UBER DO BRA | D26: 12 | E26: Transporte | G26: Recebimento (PIX Priscila) | H26: =SUMIF($E$12:$E$58,"Recebimento",$C$12:$C$58) -> 15640
A27: 46238 | B27: PIX TRANSF MARIANA | C27: 50 | E27: Recebimento | G27: Reembolso McKinsey | H27: =SUMIF($E$12:$E$58,"Reembolso",$C$12:$C$58) -> 399.07
A28: 46238 | B28: PIX TRANSF PRISCILA | C28: 700 | E28: Recebimento | G28: Devolução | H28: =SUMIF($E$12:$E$58,"Devolução",$C$12:$C$58) -> 392.56
A29: 46269 | B29: PIX QRS SECRETARIA (IPTU) | D29: 766.06 | E29: IPTU | G29: TOTAL ENTRADAS | H29: =SUM(H25:H28) -> 37961.45
A30: 46269 | B30: PIX TRANSF PRISCILA | C30: 750 | E30: Recebimento
A31: 46299 | B31: PIX TRANSF LUCIANA | D31: 22 | E31: Transferência
A32: 46360 | B32: PIX TRANSF RAFAEL | D32: 24 | E32: Transferência
A33: 13/04 | B33: PIX QRS UBER DO BRA | D33: 13.78 | E33: Transporte
A34: 13/04 | B34: Aplicação COFRINHOS | D34: 1000 | E34: Investimento
A35: 14/04 | B35: PIX QRS X FARMACIA | D35: 565.09 | E35: Farmácia
A36: 14/04 | B36: PIX TRANSF PRISCILA | C36: 2000 | E36: Recebimento
A37: 15/04 | B37: Lançamento a Débito (Financiamento) | D37: 6404.82 | E37: Financiamento
A38: 15/04 | B38: PIX TRANSF MARIANA | C38: 50 | E38: Recebimento
A39: 16/04 | B39: Remuneração/Salário | C39: 4050.39 | E39: Salário
A40: 16/04 | B40: PIX TRANSF PRISCILA | C40: 3390 | E40: Recebimento
A41: 16/04 | B41: Déb Autor PORTO SEG VIDA | D41: 105.48 | E41: Seguro
...

Sheet maio 26
A1: 📊 EXTRATO BANCÁRIO - MAIO/2026
A2: Conta: Ag 3767 | CC 29709-0 | Itaú Personnalité
A4: 📈 RESUMO DO MÊS | G4: 📊 ANÁLISE POR CATEGORIA
A5: Saldo Inicial (30/04) | B5: 26011.36 | G5: Categoria | H5: Saídas (R$) | I5: % do Total
A6: Saldo Final C/C | B6: 1 | G6: Investimento | H6: =SUMIF($E$12:$E$58,"Investimento",$D$12:$D$58) -> 17000 | I6: =H6/$H$22 -> 0.33444263
A7: Saldo Aplic Aut Mais | B7: 21480.28 | G7: Cartão | H7: =SUMIF($E$12:$E$58,"Cartão",$D$12:$D$58) -> 7540.21 | I7: =H7/$H$22 -> 0.14833928
A8: Saldo Final Total | B8: 21481.28 | G8: Escola | H8: =SUMIF($E$12:$E$58,"Escola",$D$12:$D$58) -> 7206.3 | I8: =H8/$H$22 -> 0.14177023
A9: Investimentos (CDB Metas) | B9: 61804.98 | G9: Financiamento | H9: =SUMIF($E$12:$E$58,"Financiamento",$D$12:$D$58) -> 6408.75 | I9: =H9/$H$22 -> 0.12607995
G10: Imposto | H10: =SUMIF($E$12:$E$58,"Imposto",$D$12:$D$58) -> 3501.63 | I10: =H10/$H$22 -> 0.068887903
A11: Data | B11: Descrição | C11: Entradas (R$) | D11: Saídas (R$) | E11: Categoria | G11: Transferência | H11: =SUMIF($E$12:$E$58,"Transferência",$D$12:$D$58) -> 3914 | I11: =H11/$H$22 -> 0.077000498
A12: 46117 | B12: PIX QRS CIRANDA BER (Escola) | D12: 6900.3 | E12: Escola | G12: Condomínio | H12: =SUMIF($E$12:$E$58,"Condomínio",$D$12:$D$58) -> 2906.84 | I12: =H12/$H$22 -> 0.057186543
A13: 46117 | B13: PIX QRS IMPULSO PAR | D13: 200 | E13: Compras | G13: Compras | H13: =SUMIF($E$12:$E$58,"Compras",$D$12:$D$58) -> 1071.9 | I13: =H13/$H$22 -> 0.021087592
A14: 46117 | B14: PIX TRANSF KATHIAN | D14: 230 | E14: Transferência | G14: Conta Luz | H14: =SUMIF($E$12:$E$58,"Conta Luz",$D$12:$D$58) -> 381.57 | I14: =H14/$H$22 -> 0.0075066633
A15: 46117 | B15: PIX TRANSF MARCIA | D15: 1980 | E15: Transferência | G15: Internet/TV | H15: =SUMIF($E$12:$E$58,"Internet/TV",$D$12:$D$58) -> 323.87 | I15: =H15/$H$22 -> 0.0063715256
A16: 46117 | B16: Pers Black 3608-7306 | D16: 7540.21 | E16: Cartão | G16: Farmácia | H16: =SUMIF($E$12:$E$58,"Farmácia",$D$12:$D$58) -> 285.92 | I16: =H16/$H$22 -> 0.0056249316
A17: 46117 | B17: TED CAIXA ECON F | C17: 4138.6 | E17: Recebimento | G17: Terapia | H17: =SUMIF($E$12:$E$58,"Terapia",$D$12:$D$58) -> 180 | I17: =H17/$H$22 -> 0.0035411573
A18: 46117 | B18: PIX TRANSF LARISSA | C18: 61 | E18: Recebimento | G18: Seguro | H18: =SUMIF($E$12:$E$58,"Seguro",$D$12:$D$58) -> 109.85 | I18: =H18/$H$22 -> 0.0021610896
A19: 46117 | B19: PIX TRANSF PRISCILA | C19: 3500 | E19: Recebimento | G19: IPTU | H19: =SUMIF($E$12:$E$58,"IPTU",$D$12:$D$58) -> 0 | I19: =H19/$H$22 -> 0
A20: 46117 | B20: PIX TRANSF PRISCILA | C20: 2800 | E20: Recebimento | G20: Pagamento | H20: =SUMIF($E$12:$E$58,"Pagamento",$D$12:$D$58) -> 0 | I20: =H20/$H$22 -> 0
A21: 46117 | B21: DA ELETROPAULO | D21: 381.57 | E21: Conta Luz | G21: Transporte | H21: =SUMIF($E$12:$E$58,"Transporte",$D$12:$D$58) -> 0 | I21: =H21/$H$22 -> 0
A22: 46147 | B22: PAG BOLETO CONDOMÍNIO | D22: 2906.84 | E22: Condomínio | G22: TOTAL SAÍDAS | H22: =SUM(H6:H21) -> 50830.84 | I22: 1
A23: 46147 | B23: PIX TRANSF PRISCILA | C23: 1400 | E23: Recebimento
A24: 46147 | B24: PIX TRANSF PRISCILA | C24: 2500 | E24: Recebimento | G24: 💰 ENTRADAS
A25: 46147 | B25: DA CLARO | D25: 323.87 | E25: Internet/TV | G25: Categoria | H25: Valor (R$)
A26: 46178 | B26: PIX TRANSF MARIANA | D26: 50 | E26: Transferência | G26: Salário | H26: =SUMIF($E$12:$E$58,"Salário",$C$12:$C$58) -> 16998.16
A27: 46208 | B27: PIX TRANSF PRISCILA | C27: 1200 | E27: Recebimento | G27: Recebimento (PIX diversos) | H27: =SUMIF($E$12:$E$58,"Recebimento",$C$12:$C$58) -> 28149.6
A28: 46239 | B28: PAY LEROY | D28: 871.9 | E28: Compras | G28: Reembolso McKinsey | H28: =SUMIF($E$12:$E$58,"Reembolso",$C$12:$C$58) -> 1151.83
A29: 46239 | B29: PIX TRANSF GRAN TU | D29: 85 | E29: Transferência | G29: Devolução | H29: =SUMIF($E$12:$E$58,"Devolução",$C$12:$C$58) -> 0
A30: 46239 | B30: Aplicação COFRINHOS | D30: 3000 | E30: Investimento | G30: TOTAL ENTRADAS | H30: =SUM(H26:H29) -> 46299.59
A31: 46239 | B31: Aplicação COFRINHOS | D31: 5000 | E31: Investimento
A32: 46239 | B32: Aplicação COFRINHOS | D32: 5000 | E32: Investimento
A33: 46239 | B33: PIX TRANSF PRISCILA | C33: 1400 | E33: Recebimento
A34: 46239 | B34: TED McKINSEY | C34: 126 | E34: Reembolso
A35: 46331 | B35: TED McKINSEY | C35: 214.85 | E35: Reembolso
A36: 46361 | B36: PIX TRANSF PRISCILA | C36: 3000 | E36: Recebimento
A37: 13/05 | B37: PIX TRANSF JOSE MA | D37: 530 | E37: Transferência
A38: 14/05 | B38: PIX QRS Ciranda Ber (Material) | D38: 126 | E38: Escola
A39: 14/05 | B39: PIX QRS X FARMACIA | D39: 199.64 | E39: Farmácia
A40: 14/05 | B40: PIX TRANSF RODA VI | D40: 195 | E40: Transferência
A41: 15/05 | B41: Lançamento a Débito (Financiamento) | D41: 6408.75 | E41: Financiamento
...

Sheet Consolidado Jan-Mai
A1: 📊 ANÁLISE CONSOLIDADA POR CATEGORIA - JANEIRO A MAIO/2026 | I1: 💡 INSIGHTS FINANCEIROS | U1: 🏆 RANKING DE GASTOS (5 meses)
A2: Conta: Ag 3767 | CC 29709-0 | Itaú Personnalité | U2: Categoria | V2: Valor Total
I3: 📊 GASTOS REAIS (excluindo investimentos e transf. internas) | U3: Cartão | V3: =G6 -> 42118.14
A4: 💸 SAÍDAS POR CATEGORIA | I4: Mês | J4: Total Saídas | K4: (-) Investimento | L4: (-) Transf. Interna | M4: {=GASTO REAL} -> #NAME? | N4: % vs Total | U4: Escola | V4: =G8 -> 36066.69
A5: Categoria | B5: Janeiro | C5: Fevereiro | D5: Março | E5: Abril | F5: Maio | G5: TOTAL | I5: Janeiro | J5: =B31 -> 87588.14 | K5: =B12 -> 0 | L5: =B10 -> 45500 | M5: =J5-K5-L5 -> 42088.14 | N5: =M5/J5 -> 0.48052328 | U5: Financiamento | V5: =G7 -> 32019.47
A6: Cartão | B6: =SUMIF('janeiro 26'!$E:$E,"Cartão",'janeiro 26'!$D:$D) -> 16607.75 | C6: =SUMIF('fevereiro 26'!$E:$E,"Cartão",'fevereiro 26'!$D:$D) -> 2589.71 | D6: =SUMIF('março 26'!$E:$E,"Cartão",'março 26'!$D:$D) -> 1660.06 | E6: =SUMIF('abril 26'!$E:$E,"Cartão",'abril 26'!$D:$D) -> 13720.41 | F6: =SUMIF('maio 26'!$E:$E,"Cartão",'maio 26'!$D:$D) -> 7540.21 | G6: =SUM(B6:F6) -> 42118.14 | I6: Fevereiro | J6: =C31 -> 32688.76 | K6: =C12 -> 0 | L6: =C10 -> 2964 | M6: =J6-K6-L6 -> 29724.76 | N6: =M6/J6 -> 0.90932663 | U6: Transferência | V6: =G9 -> 25840.77
A7: Financiamento | B7: =SUMIF('janeiro 26'!$E:$E,"Financiamento",'janeiro 26'!$D:$D) -> 6404.66 | C7: =SUMIF('fevereiro 26'!$E:$E,"Financiamento",'fevereiro 26'!$D:$D) -> 6403.15 | D7: =SUMIF('março 26'!$E:$E,"Financiamento",'março 26'!$D:$D) -> 6398.09 | E7: =SUMIF('abril 26'!$E:$E,"Financiamento",'abril 26'!$D:$D) -> 6404.82 | F7: =SUMIF('maio 26'!$E:$E,"Financiamento",'maio 26'!$D:$D) -> 6408.75 | G7: =SUM(B7:F7) -> 32019.47 | I7: Março | J7: =D31 -> 86875.34 | K7: =D12 -> 42620 | L7: =D10 -> 3000 | M7: =J7-K7-L7 -> 41255.34 | N7: =M7/J7 -> 0.47487975 | U7: Condomínio | V7: =G11 -> 7538.34
A8: Escola | B8: =SUMIF('janeiro 26'!$E:$E,"Escola",'janeiro 26'!$D:$D) -> 3788.01 | C8: =SUMIF('fevereiro 26'!$E:$E,"Escola",'fevereiro 26'!$D:$D) -> 11078.78 | D8: =SUMIF('março 26'!$E:$E,"Escola",'março 26'!$D:$D) -> 13800.6 | E8: =SUMIF('abril 26'!$E:$E,"Escola",'abril 26'!$D:$D) -> 193 | F8: =SUMIF('maio 26'!$E:$E,"Escola",'maio 26'!$D:$D) -> 7206.3 | G8: =SUM(B8:F8) -> 36066.69 | I8: Abril | J8: =E31 -> 32607.71 | K8: =E12 -> 1000 | L8: =E10 -> 0 | M8: =J8-K8-L8 -> 31607.71 | N8: =M8/J8 -> 0.96933241 | U8: Terapia + Psicologia | V8: =G13+G14 -> 8170
A9: Transferência | B9: =SUMIF('janeiro 26'!$E:$E,"Transferência",'janeiro 26'!$D:$D) -> 7521.28 | C9: =SUMIF('fevereiro 26'!$E:$E,"Transferência",'fevereiro 26'!$D:$D) -> 3587 | D9: =SUMIF('março 26'!$E:$E,"Transferência",'março 26'!$D:$D) -> 9446.99 | E9: =SUMIF('abril 26'!$E:$E,"Transferência",'abril 26'!$D:$D) -> 1371.5 | F9: =SUMIF('maio 26'!$E:$E,"Transferência",'maio 26'!$D:$D) -> 3914 | G9: =SUM(B9:F9) -> 25840.77 | I9: Maio | J9: =F31 -> 50830.84 | K9: =F12 -> 17000 | L9: =F10 -> 0 | M9: =J9-K9-L9 -> 33830.84 | N9: =M9/J9 -> 0.66555737 | U9: Compras | V9: =G15 -> 6993.31
A10: Transferência Interna | B10: =SUMIF('janeiro 26'!$E:$E,"Transferência Interna",'janeiro 26'!$D:$D) -> 45500 | C10: =SUMIF('fevereiro 26'!$E:$E,"Transferência Interna",'fevereiro 26'!$D:$D) -> 2964 | D10: =SUMIF('março 26'!$E:$E,"Transferência Interna",'março 26'!$D:$D) -> 3000 | E10: =SUMIF('abril 26'!$E:$E,"Transferência Interna",'abril 26'!$D:$D) -> 0 | F10: =SUMIF('maio 26'!$E:$E,"Transferência Interna",'maio 26'!$D:$D) -> 0 | G10: =SUM(B10:F10) -> 51464 | I10: TOTAL | J10: =SUM(J5:J9) -> 290590.79 | K10: =SUM(K5:K9) -> 60620 | L10: =SUM(L5:L9) -> 51464 | M10: =SUM(M5:M9) -> 178506.79 | N10: =M10/J10 -> 0.61428922 | U10: Pagamento | V10: =G22 -> 5231.83
A11: Condomínio | B11: =SUMIF('janeiro 26'!$E:$E,"Condomínio",'janeiro 26'!$D:$D) -> 0 | C11: =SUMIF('fevereiro 26'!$E:$E,"Condomínio",'fevereiro 26'!$D:$D) -> 0 | D11: =SUMIF('março 26'!$E:$E,"Condomínio",'março 26'!$D:$D) -> 2290.55 | E11: =SUMIF('abril 26'!$E:$E,"Condomínio",'abril 26'!$D:$D) -> 2340.95 | F11: =SUMIF('maio 26'!$E:$E,"Condomínio",'maio 26'!$D:$D) -> 2906.84 | G11: =SUM(B11:F11) -> 7538.34 | U11: Imposto | V11: =G21 -> 3501.63
A12: Investimento | B12: =SUMIF('janeiro 26'!$E:$E,"Investimento",'janeiro 26'!$D:$D) -> 0 | C12: =SUMIF('fevereiro 26'!$E:$E,"Investimento",'fevereiro 26'!$D:$D) -> 0 | D12: =SUMIF('março 26'!$E:$E,"Investimento",'março 26'!$D:$D) -> 42620 | E12: =SUMIF('abril 26'!$E:$E,"Investimento",'abril 26'!$D:$D) -> 1000 | F12: =SUMIF('maio 26'!$E:$E,"Investimento",'maio 26'!$D:$D) -> 17000 | G12: =SUM(B12:F12) -> 60620 | I12: 🏆 TOP 5 MAIORES GASTOS (5 meses) | U12: IPTU | V12: =G20 -> 2298.18
A13: Terapia | B13: =SUMIF('janeiro 26'!$E:$E,"Terapia",'janeiro 26'!$D:$D) -> 0 | C13: =SUMIF('fevereiro 26'!$E:$E,"Terapia",'fevereiro 26'!$D:$D) -> 610 | D13: =SUMIF('março 26'!$E:$E,"Terapia",'março 26'!$D:$D) -> 0 | E13: =SUMIF('abril 26'!$E:$E,"Terapia",'abril 26'!$D:$D) -> 3380 | F13: =SUMIF('maio 26'!$E:$E,"Terapia",'maio 26'!$D:$D) -> 180 | G13: =SUM(B13:F13) -> 4170 | I13: # | J13: Categoria | K13: Valor Total | U13: Conta Luz | V13: =G19 -> 1855.95
A14: Terapia/Psicologia | B14: =SUMIF('janeiro 26'!$E:$E,"Terapia/Psicologia",'janeiro 26'!$D:$D) -> 4000 | C14: =SUMIF('fevereiro 26'!$E:$E,"Terapia/Psicologia",'fevereiro 26'!$D:$D) -> 0 | D14: =SUMIF('março 26'!$E:$E,"Terapia/Psicologia",'março 26'!$D:$D) -> 0 | E14: =SUMIF('abril 26'!$E:$E,"Terapia/Psicologia",'abril 26'!$D:$D) -> 0 | F14: =SUMIF('maio 26'!$E:$E,"Terapia/Psicologia",'maio 26'!$D:$D) -> 0 | G14: =SUM(B14:F14) -> 4000 | I14: 1º | J14: Investimento | K14: =G12 -> 60620 | U14: Farmácia | V14: =G16 -> 1717.87
A15: Compras | B15: =SUMIF('janeiro 26'!$E:$E,"Compras",'janeiro 26'!$D:$D) -> 979.85 | C15: =SUMIF('fevereiro 26'!$E:$E,"Compras",'fevereiro 26'!$D:$D) -> 1757.1 | D15: =SUMIF('março 26'!$E:$E,"Compras",'março 26'!$D:$D) -> 2764.33 | E15: =SUMIF('abril 26'!$E:$E,"Compras",'abril 26'!$D:$D) -> 420.13 | F15: =SUMIF('maio 26'!$E:$E,"Compras",'maio 26'!$D:$D) -> 1071.9 | G15: =SUM(B15:F15) -> 6993.31 | I15: 2º | J15: Transferência Interna | K15: =G10 -> 51464
A16: Farmácia | B16: =SUMIF('janeiro 26'!$E:$E,"Farmácia",'janeiro 26'!$D:$D) -> 303.84 | C16: =SUMIF('fevereiro 26'!$E:$E,"Farmácia",'fevereiro 26'!$D:$D) -> 143.91 | D16: =SUMIF('março 26'!$E:$E,"Farmácia",'março 26'!$D:$D) -> 0 | E16: =SUMIF('abril 26'!$E:$E,"Farmácia",'abril 26'!$D:$D) -> 984.2 | F16: =SUMIF('maio 26'!$E:$E,"Farmácia",'maio 26'!$D:$D) -> 285.92 | G16: =SUM(B16:F16) -> 1717.87 | I16: 3º | J16: Cartão | K16: =G6 -> 42118.14
A17: Alimentação | B17: =SUMIF('janeiro 26'!$E:$E,"Alimentação",'janeiro 26'!$D:$D) -> 232.84 | C17: =SUMIF('fevereiro 26'!$E:$E,"Alimentação",'fevereiro 26'!$D:$D) -> 786.29 | D17: =SUMIF('março 26'!$E:$E,"Alimentação",'março 26'!$D:$D) -> 0 | E17: =SUMIF('abril 26'!$E:$E,"Alimentação",'abril 26'!$D:$D) -> 0 | F17: =SUMIF('maio 26'!$E:$E,"Alimentação",'maio 26'!$D:$D) -> 0 | G17: =SUM(B17:F17) -> 1019.13 | I17: 4º | J17: Escola | K17: =G8 -> 36066.69
A18: Internet/TV | B18: =SUMIF('janeiro 26'!$E:$E,"Internet/TV",'janeiro 26'!$D:$D) -> 323.87 | C18: =SUMIF('fevereiro 26'!$E:$E,"Internet/TV",'fevereiro 26'!$D:$D) -> 323.87 | D18: =SUMIF('março 26'!$E:$E,"Internet/TV",'março 26'!$D:$D) -> 321.01 | E18: =SUMIF('abril 26'!$E:$E,"Internet/TV",'abril 26'!$D:$D) -> 323.87 | F18: =SUMIF('maio 26'!$E:$E,"Internet/TV",'maio 26'!$D:$D) -> 323.87 | G18: =SUM(B18:F18) -> 1616.49 | I18: 5º | J18: Financiamento | K18: =G7 -> 32019.47
A19: Conta Luz | B19: =SUMIF('janeiro 26'!$E:$E,"Conta Luz",'janeiro 26'!$D:$D) -> 327.82 | C19: =SUMIF('fevereiro 26'!$E:$E,"Conta Luz",'fevereiro 26'!$D:$D) -> 451.49 | D19: =SUMIF('março 26'!$E:$E,"Conta Luz",'março 26'!$D:$D) -> 360.61 | E19: =SUMIF('abril 26'!$E:$E,"Conta Luz",'abril 26'!$D:$D) -> 334.46 | F19: =SUMIF('maio 26'!$E:$E,"Conta Luz",'maio 26'!$D:$D) -> 381.57 | G19: =SUM(B19:F19) -> 1855.95
A20: IPTU | B20: =SUMIF('janeiro 26'!$E:$E,"IPTU",'janeiro 26'!$D:$D) -> 0 | C20: =SUMIF('fevereiro 26'!$E:$E,"IPTU",'fevereiro 26'!$D:$D) -> 766.06 | D20: =SUMIF('março 26'!$E:$E,"IPTU",'março 26'!$D:$D) -> 766.06 | E20: =SUMIF('abril 26'!$E:$E,"IPTU",'abril 26'!$D:$D) -> 766.06 | F20: =SUMIF('maio 26'!$E:$E,"IPTU",'maio 26'!$D:$D) -> 0 | G20: =SUM(B20:F20) -> 2298.18 | I20: 📌 GASTOS FIXOS MENSAIS
A21: Imposto | B21: =SUMIF('janeiro 26'!$E:$E,"Imposto",'janeiro 26'!$D:$D) -> 0 | C21: =SUMIF('fevereiro 26'!$E:$E,"Imposto",'fevereiro 26'!$D:$D) -> 0 | D21: =SUMIF('março 26'!$E:$E,"Imposto",'março 26'!$D:$D) -> 0 | E21: =SUMIF('abril 26'!$E:$E,"Imposto",'abril 26'!$D:$D) -> 0 | F21: =SUMIF('maio 26'!$E:$E,"Imposto",'maio 26'!$D:$D) -> 3501.63 | G21: =SUM(B21:F21) -> 3501.63 | I21: Categoria | J21: Valor Médio/Mês | K21: % do Total
A22: Pagamento | B22: =SUMIF('janeiro 26'!$E:$E,"Pagamento",'janeiro 26'!$D:$D) -> 490.61 | C22: =SUMIF('fevereiro 26'!$E:$E,"Pagamento",'fevereiro 26'!$D:$D) -> 233.59 | D22: =SUMIF('março 26'!$E:$E,"Pagamento",'março 26'!$D:$D) -> 3270.58 | E22: =SUMIF('abril 26'!$E:$E,"Pagamento",'abril 26'!$D:$D) -> 1237.05 | F22: =SUMIF('maio 26'!$E:$E,"Pagamento",'maio 26'!$D:$D) -> 0 | G22: =SUM(B22:F22) -> 5231.83 | I22: Financiamento Imobiliário | J22: =G7/5 -> 6403.894 | K22: =G7/G31 -> 0.11018749
A23: Seguro | B23: =SUMIF('janeiro 26'!$E:$E,"Seguro",'janeiro 26'!$D:$D) -> 105.48 | C23: =SUMIF('fevereiro 26'!$E:$E,"Seguro",'fevereiro 26'!$D:$D) -> 105.48 | D23: =SUMIF('março 26'!$E:$E,"Seguro",'março 26'!$D:$D) -> 105.48 | E23: =SUMIF('abril 26'!$E:$E,"Seguro",'abril 26'!$D:$D) -> 105.48 | F23: =SUMIF('maio 26'!$E:$E,"Seguro",'maio 26'!$D:$D) -> 109.85 | G23: =SUM(B23:F23) -> 531.77 | I23: Internet/TV | J23: =G18/5 -> 323.298 | K23: =G18/G31 -> 0.0055627709
A24: Telefone | B24: =SUMIF('janeiro 26'!$E:$E,"Telefone",'janeiro 26'!$D:$D) -> 82.13 | C24: =SUMIF('fevereiro 26'!$E:$E,"Telefone",'fevereiro 26'!$D:$D) -> 85.2 | D24: =SUMIF('março 26'!$E:$E,"Telefone",'março 26'!$D:$D) -> 0 | E24: =SUMIF('abril 26'!$E:$E,"Telefone",'abril 26'!$D:$D) -> 0 | F24: =SUMIF('maio 26'!$E:$E,"Telefone",'maio 26'!$D:$D) -> 0 | G24: =SUM(B24:F24) -> 167.33 | I24: Conta de Luz | J24: =G19/5 -> 371.19 | K24: =G19/G31 -> 0.0063868163
A25: Transporte | B25: =SUMIF('janeiro 26'!$E:$E,"Transporte",'janeiro 26'!$D:$D) -> 0 | C25: =SUMIF('fevereiro 26'!$E:$E,"Transporte",'fevereiro 26'!$D:$D) -> 27 | D25: =SUMIF('março 26'!$E:$E,"Transporte",'março 26'!$D:$D) -> 27.98 | E25: =SUMIF('abril 26'!$E:$E,"Transporte",'abril 26'!$D:$D) -> 25.78 | F25: =SUMIF('maio 26'!$E:$E,"Transporte",'maio 26'!$D:$D) -> 0 | G25: =SUM(B25:F25) -> 80.76 | I25: Seguro | J25: =G23/5 -> 106.354 | K25: =G23/G31 -> 0.0018299616
A26: Lazer | B26: =SUMIF('janeiro 26'!$E:$E,"Lazer",'janeiro 26'!$D:$D) -> 0 | C26: =SUMIF('fevereiro 26'!$E:$E,"Lazer",'fevereiro 26'!$D:$D) -> 578.13 | D26: =SUMIF('março 26'!$E:$E,"Lazer",'março 26'!$D:$D) -> 0 | E26: =SUMIF('abril 26'!$E:$E,"Lazer",'abril 26'!$D:$D) -> 0 | F26: =SUMIF('maio 26'!$E:$E,"Lazer",'maio 26'!$D:$D) -> 0 | G26: =SUM(B26:F26) -> 578.13 | I26: TOTAL FIXOS | J26: =SUM(J22:J25) -> 7204.736 | K26: =SUM(K22:K25) -> 0.12396704
A27: Serviços | B27: =SUMIF('janeiro 26'!$E:$E,"Serviços",'janeiro 26'!$D:$D) -> 920 | C27: =SUMIF('fevereiro 26'!$E:$E,"Serviços",'fevereiro 26'!$D:$D) -> 0 | D27: =SUMIF('março 26'!$E:$E,"Serviços",'março 26'!$D:$D) -> 0 | E27: =SUMIF('abril 26'!$E:$E,"Serviços",'abril 26'!$D:$D) -> 0 | F27: =SUMIF('maio 26'!$E:$E,"Serviços",'maio 26'!$D:$D) -> 0 | G27: =SUM(B27:F27) -> 920
A28: Assinatura | B28: =SUMIF('janeiro 26'!$E:$E,"Assinatura",'janeiro 26'!$D:$D) -> 0 | C28: =SUMIF('fevereiro 26'!$E:$E,"Assinatura",'fevereiro 26'!$D:$D) -> 150 | D28: =SUMIF('março 26'!$E:$E,"Assinatura",'março 26'!$D:$D) -> 0 | E28: =SUMIF('abril 26'!$E:$E,"Assinatura",'abril 26'!$D:$D) -> 0 | F28: =SUMIF('maio 26'!$E:$E,"Assinatura",'maio 26'!$D:$D) -> 0 | G28: =SUM(B28:F28) -> 150 | I28: ❤️ INDICADORES DE SAÚDE FINANCEIRA
A29: Saúde | B29: =SUMIF('janeiro 26'!$E:$E,"Saúde",'janeiro 26'!$D:$D) -> 0 | C29: =SUMIF('fevereiro 26'!$E:$E,"Saúde",'fevereiro 26'!$D:$D) -> 48 | D29: =SUMIF('março 26'!$E:$E,"Saúde",'março 26'!$D:$D) -> 0 | E29: =SUMIF('abril 26'!$E:$E,"Saúde",'abril 26'!$D:$D) -> 0 | F29: =SUMIF('maio 26'!$E:$E,"Saúde",'maio 26'!$D:$D) -> 0 | G29: =SUM(B29:F29) -> 48 | I29: Indicador | J29: Valor | K29: Meta | L29: Status
A30: Estacionamento | B30: =SUMIF('janeiro 26'!$E:$E,"Estacionamento",'janeiro 26'!$D:$D) -> 0 | C30: =SUMIF('fevereiro 26'!$E:$E,"Estacionamento",'fevereiro 26'!$D:$D) -> 0 | D30: =SUMIF('março 26'!$E:$E,"Estacionamento",'março 26'!$D:$D) -> 43 | E30: =SUMIF('abril 26'!$E:$E,"Estacionamento",'abril 26'!$D:$D) -> 0 | F30: =SUMIF('maio 26'!$E:$E,"Estacionamento",'maio 26'!$D:$D) -> 0 | G30: =SUM(B30:F30) -> 43 | I30: Taxa de Poupança | J30: =G12/G42 -> 0.19788665 | K30: 0.2 | L30: =IF(J30>=0.2,"✅ Ótimo",IF(J30>=0.1,"⚠️ Regular","❌ Baixo")) -> ⚠️ Regular
